[2025-05-02T15:18:29.097+0000] {taskinstance.py:1956} INFO - Dependencies all met for dep_context=non-requeueable deps ti=<TaskInstance: process_etl_stroke_data.feature_engineering scheduled__2025-05-01T00:00:00+00:00 [queued]>
[2025-05-02T15:18:29.104+0000] {taskinstance.py:1956} INFO - Dependencies all met for dep_context=requeueable deps ti=<TaskInstance: process_etl_stroke_data.feature_engineering scheduled__2025-05-01T00:00:00+00:00 [queued]>
[2025-05-02T15:18:29.105+0000] {taskinstance.py:2170} INFO - Starting attempt 2 of 2
[2025-05-02T15:18:29.115+0000] {taskinstance.py:2191} INFO - Executing <Task(_PythonVirtualenvDecoratedOperator): feature_engineering> on 2025-05-01 00:00:00+00:00
[2025-05-02T15:18:29.119+0000] {standard_task_runner.py:60} INFO - Started process 886 to run task
[2025-05-02T15:18:29.122+0000] {standard_task_runner.py:87} INFO - Running: ['***', 'tasks', 'run', 'process_etl_stroke_data', 'feature_engineering', 'scheduled__2025-05-01T00:00:00+00:00', '--job-id', '4', '--raw', '--subdir', 'DAGS_FOLDER/etl_processing.py', '--cfg-path', '/tmp/tmp5o4aany8']
[2025-05-02T15:18:29.126+0000] {standard_task_runner.py:88} INFO - Job 4: Subtask feature_engineering
[2025-05-02T15:18:29.167+0000] {task_command.py:423} INFO - Running <TaskInstance: process_etl_stroke_data.feature_engineering scheduled__2025-05-01T00:00:00+00:00 [running]> on host 612cef286438
[2025-05-02T15:18:29.222+0000] {taskinstance.py:2480} INFO - Exporting env vars: AIRFLOW_CTX_DAG_OWNER='Brain Stroke Project' AIRFLOW_CTX_DAG_ID='process_etl_stroke_data' AIRFLOW_CTX_TASK_ID='feature_engineering' AIRFLOW_CTX_EXECUTION_DATE='2025-05-01T00:00:00+00:00' AIRFLOW_CTX_TRY_NUMBER='2' AIRFLOW_CTX_DAG_RUN_ID='scheduled__2025-05-01T00:00:00+00:00'
[2025-05-02T15:18:29.224+0000] {process_utils.py:182} INFO - Executing cmd: /usr/local/bin/python -m virtualenv /tmp/venvfk7u99h7 --system-site-packages --python=python
[2025-05-02T15:18:29.230+0000] {process_utils.py:186} INFO - Output:
[2025-05-02T15:18:29.812+0000] {process_utils.py:190} INFO - created virtual environment CPython3.8.18.final.0-64 in 316ms
[2025-05-02T15:18:29.813+0000] {process_utils.py:190} INFO -   creator CPython3Posix(dest=/tmp/venvfk7u99h7, clear=False, no_vcs_ignore=False, global=True)
[2025-05-02T15:18:29.814+0000] {process_utils.py:190} INFO -   seeder FromAppData(download=False, pip=bundle, setuptools=bundle, wheel=bundle, via=copy, app_data_dir=/tmp/tmpkdi_4yfx)
[2025-05-02T15:18:29.815+0000] {process_utils.py:190} INFO -     added seed packages: pip==23.3.1, setuptools==69.0.2, wheel==0.42.0
[2025-05-02T15:18:29.815+0000] {process_utils.py:190} INFO -   activators BashActivator,CShellActivator,FishActivator,NushellActivator,PowerShellActivator,PythonActivator
[2025-05-02T15:18:29.838+0000] {process_utils.py:182} INFO - Executing cmd: /tmp/venvfk7u99h7/bin/pip install -r /tmp/venvfk7u99h7/requirements.txt
[2025-05-02T15:18:29.845+0000] {process_utils.py:186} INFO - Output:
[2025-05-02T15:18:30.486+0000] {process_utils.py:190} INFO - WARNING: The directory '/home/***/.cache/pip' or its parent directory is not owned or is not writable by the current user. The cache has been disabled. Check the permissions and owner of that directory. If executing pip with sudo, you should use sudo's -H flag.
[2025-05-02T15:18:30.704+0000] {process_utils.py:190} INFO - Collecting awswrangler==3.9.1 (from -r /tmp/venvfk7u99h7/requirements.txt (line 1))
[2025-05-02T15:18:30.766+0000] {process_utils.py:190} INFO -   Downloading awswrangler-3.9.1-py3-none-any.whl.metadata (17 kB)
[2025-05-02T15:18:30.802+0000] {process_utils.py:190} INFO - Requirement already satisfied: boto3<2.0.0,>=1.20.32 in /home/***/.local/lib/python3.8/site-packages (from awswrangler==3.9.1->-r /tmp/venvfk7u99h7/requirements.txt (line 1)) (1.37.38)
[2025-05-02T15:18:30.803+0000] {process_utils.py:190} INFO - Requirement already satisfied: botocore<2.0.0,>=1.23.32 in /home/***/.local/lib/python3.8/site-packages (from awswrangler==3.9.1->-r /tmp/venvfk7u99h7/requirements.txt (line 1)) (1.37.38)
[2025-05-02T15:18:30.804+0000] {process_utils.py:190} INFO - Requirement already satisfied: numpy<2.0,>=1.18 in /home/***/.local/lib/python3.8/site-packages (from awswrangler==3.9.1->-r /tmp/venvfk7u99h7/requirements.txt (line 1)) (1.24.4)
[2025-05-02T15:18:30.805+0000] {process_utils.py:190} INFO - Requirement already satisfied: packaging<25.0,>=21.1 in /home/***/.local/lib/python3.8/site-packages (from awswrangler==3.9.1->-r /tmp/venvfk7u99h7/requirements.txt (line 1)) (23.2)
[2025-05-02T15:18:30.806+0000] {process_utils.py:190} INFO - Requirement already satisfied: pandas<2.1.0,>=1.2.0 in /home/***/.local/lib/python3.8/site-packages (from awswrangler==3.9.1->-r /tmp/venvfk7u99h7/requirements.txt (line 1)) (2.0.3)
[2025-05-02T15:18:30.806+0000] {process_utils.py:190} INFO - Requirement already satisfied: pyarrow>=8.0.0 in /home/***/.local/lib/python3.8/site-packages (from awswrangler==3.9.1->-r /tmp/venvfk7u99h7/requirements.txt (line 1)) (14.0.2)
[2025-05-02T15:18:30.807+0000] {process_utils.py:190} INFO - Requirement already satisfied: typing-extensions<5.0.0,>=4.4.0 in /home/***/.local/lib/python3.8/site-packages (from awswrangler==3.9.1->-r /tmp/venvfk7u99h7/requirements.txt (line 1)) (4.9.0)
[2025-05-02T15:18:30.810+0000] {process_utils.py:190} INFO - Requirement already satisfied: jmespath<2.0.0,>=0.7.1 in /home/***/.local/lib/python3.8/site-packages (from boto3<2.0.0,>=1.20.32->awswrangler==3.9.1->-r /tmp/venvfk7u99h7/requirements.txt (line 1)) (0.10.0)
[2025-05-02T15:18:30.811+0000] {process_utils.py:190} INFO - Requirement already satisfied: s3transfer<0.12.0,>=0.11.0 in /home/***/.local/lib/python3.8/site-packages (from boto3<2.0.0,>=1.20.32->awswrangler==3.9.1->-r /tmp/venvfk7u99h7/requirements.txt (line 1)) (0.11.5)
[2025-05-02T15:18:30.816+0000] {process_utils.py:190} INFO - Requirement already satisfied: python-dateutil<3.0.0,>=2.1 in /home/***/.local/lib/python3.8/site-packages (from botocore<2.0.0,>=1.23.32->awswrangler==3.9.1->-r /tmp/venvfk7u99h7/requirements.txt (line 1)) (2.8.2)
[2025-05-02T15:18:30.817+0000] {process_utils.py:190} INFO - Requirement already satisfied: urllib3<1.27,>=1.25.4 in /home/***/.local/lib/python3.8/site-packages (from botocore<2.0.0,>=1.23.32->awswrangler==3.9.1->-r /tmp/venvfk7u99h7/requirements.txt (line 1)) (1.26.18)
[2025-05-02T15:18:30.876+0000] {process_utils.py:190} INFO - Requirement already satisfied: pytz>=2020.1 in /home/***/.local/lib/python3.8/site-packages (from pandas<2.1.0,>=1.2.0->awswrangler==3.9.1->-r /tmp/venvfk7u99h7/requirements.txt (line 1)) (2023.3.post1)
[2025-05-02T15:18:30.877+0000] {process_utils.py:190} INFO - Requirement already satisfied: tzdata>=2022.1 in /home/***/.local/lib/python3.8/site-packages (from pandas<2.1.0,>=1.2.0->awswrangler==3.9.1->-r /tmp/venvfk7u99h7/requirements.txt (line 1)) (2023.4)
[2025-05-02T15:18:30.884+0000] {process_utils.py:190} INFO - Requirement already satisfied: six>=1.5 in /home/***/.local/lib/python3.8/site-packages (from python-dateutil<3.0.0,>=2.1->botocore<2.0.0,>=1.23.32->awswrangler==3.9.1->-r /tmp/venvfk7u99h7/requirements.txt (line 1)) (1.16.0)
[2025-05-02T15:18:30.910+0000] {process_utils.py:190} INFO - Downloading awswrangler-3.9.1-py3-none-any.whl (381 kB)
[2025-05-02T15:18:30.935+0000] {process_utils.py:190} INFO -    ━━━━━━━━━━━━━━━━━━━━━━━━━━━━━━━━━━━━━━━━ 381.7/381.7 kB 17.8 MB/s eta 0:00:00
[2025-05-02T15:18:33.040+0000] {process_utils.py:190} INFO - Installing collected packages: awswrangler
[2025-05-02T15:18:33.217+0000] {process_utils.py:190} INFO - Successfully installed awswrangler-3.9.1
[2025-05-02T15:18:33.304+0000] {process_utils.py:190} INFO - 
[2025-05-02T15:18:33.305+0000] {process_utils.py:190} INFO - [notice] A new release of pip is available: 23.3.1 -> 25.0.1
[2025-05-02T15:18:33.306+0000] {process_utils.py:190} INFO - [notice] To update, run: python -m pip install --upgrade pip
[2025-05-02T15:18:33.476+0000] {process_utils.py:182} INFO - Executing cmd: /tmp/venvfk7u99h7/bin/python /tmp/venv-call_q98sfru/script.py /tmp/venv-call_q98sfru/script.in /tmp/venv-call_q98sfru/script.out /tmp/venv-call_q98sfru/string_args.txt /tmp/venv-call_q98sfru/termination.log
[2025-05-02T15:18:33.483+0000] {process_utils.py:186} INFO - Output:
[2025-05-02T15:18:34.057+0000] {process_utils.py:190} INFO - WARNING:root:/opt/***/logs/scheduler/latest already exists as a dir/file. Skip creating symlink.
[2025-05-02T15:18:35.319+0000] {process_utils.py:190} INFO - [[34m2025-05-02T15:18:35.318+0000[0m] {[34mscript.py:[0m61} INFO[0m - Loading dataset from S3/Minio[0m
[2025-05-02T15:18:35.330+0000] {process_utils.py:190} INFO - [[34m2025-05-02T15:18:35.329+0000[0m] {[34mcredentials.py:[0m1213} INFO[0m - Found credentials in environment variables.[0m
[2025-05-02T15:18:35.463+0000] {process_utils.py:190} INFO - [[34m2025-05-02T15:18:35.463+0000[0m] {[34mconfigprovider.py:[0m998} INFO[0m - Found endpoint for s3 via: environment_service.[0m
[2025-05-02T15:18:35.509+0000] {process_utils.py:190} INFO - [[34m2025-05-02T15:18:35.508+0000[0m] {[34mscript.py:[0m69} INFO[0m - Dataset loaded successfully from s3://data/raw/stroke_data.csv[0m
[2025-05-02T15:18:35.510+0000] {process_utils.py:190} INFO - [[34m2025-05-02T15:18:35.509+0000[0m] {[34mscript.py:[0m70} INFO[0m - Dataset shape: (5110, 12)[0m
[2025-05-02T15:18:35.510+0000] {process_utils.py:190} INFO - [[34m2025-05-02T15:18:35.509+0000[0m] {[34mscript.py:[0m71} INFO[0m - Dataset columns: ['id', 'gender', 'age', 'hypertension', 'heart_disease', 'ever_married', 'work_type', 'residence_type', 'avg_glucose_level', 'bmi', 'smoking_status', 'stroke'][0m
[2025-05-02T15:18:35.511+0000] {process_utils.py:190} INFO - [[34m2025-05-02T15:18:35.509+0000[0m] {[34mscript.py:[0m77} INFO[0m - Limpiando datos eliminando duplicados y manejando valores nulos[0m
[2025-05-02T15:18:35.512+0000] {process_utils.py:190} INFO - [[34m2025-05-02T15:18:35.511+0000[0m] {[34mscript.py:[0m84} INFO[0m - Removed 0 duplicate rows[0m
[2025-05-02T15:18:35.513+0000] {process_utils.py:190} INFO - [[34m2025-05-02T15:18:35.513+0000[0m] {[34mscript.py:[0m98} INFO[0m - No null values remaining in the dataset[0m
[2025-05-02T15:18:35.514+0000] {process_utils.py:190} INFO - [[34m2025-05-02T15:18:35.513+0000[0m] {[34mscript.py:[0m101} INFO[0m - Iniciando ingeniería de características[0m
[2025-05-02T15:18:35.515+0000] {process_utils.py:190} INFO - [[34m2025-05-02T15:18:35.513+0000[0m] {[34mscript.py:[0m55} INFO[0m - Applying One-Hot Encoding to columns: ['gender', 'ever_married', 'work_type', 'residence_type', 'smoking_status'][0m
[2025-05-02T15:18:35.518+0000] {process_utils.py:190} INFO - [[34m2025-05-02T15:18:35.517+0000[0m] {[34mscript.py:[0m108} INFO[0m - Applied one-hot encoding to categorical features[0m
[2025-05-02T15:18:35.519+0000] {process_utils.py:190} INFO - [[34m2025-05-02T15:18:35.518+0000[0m] {[34mscript.py:[0m113} INFO[0m - Removed 'id' column as it's not relevant for prediction[0m
[2025-05-02T15:18:35.520+0000] {process_utils.py:190} INFO - [[34m2025-05-02T15:18:35.520+0000[0m] {[34mscript.py:[0m122} INFO[0m - Truncated extreme values in 'age' column at 82.0[0m
[2025-05-02T15:18:35.521+0000] {process_utils.py:190} INFO - [[34m2025-05-02T15:18:35.521+0000[0m] {[34mscript.py:[0m122} INFO[0m - Truncated extreme values in 'avg_glucose_level' column at 240.7082[0m
[2025-05-02T15:18:35.522+0000] {process_utils.py:190} INFO - [[34m2025-05-02T15:18:35.522+0000[0m] {[34mscript.py:[0m122} INFO[0m - Truncated extreme values in 'bmi' column at 66.6[0m
[2025-05-02T15:18:35.523+0000] {process_utils.py:190} INFO - [[34m2025-05-02T15:18:35.522+0000[0m] {[34mscript.py:[0m124} INFO[0m - Feature engineering completed[0m
[2025-05-02T15:18:35.524+0000] {process_utils.py:190} INFO - [[34m2025-05-02T15:18:35.522+0000[0m] {[34mscript.py:[0m127} INFO[0m - Saving processed dataset to s3://data/processed/stroke_data.csv[0m
[2025-05-02T15:18:35.531+0000] {process_utils.py:190} INFO - [[34m2025-05-02T15:18:35.531+0000[0m] {[34mcredentials.py:[0m1213} INFO[0m - Found credentials in environment variables.[0m
[2025-05-02T15:18:35.581+0000] {process_utils.py:190} INFO - [[34m2025-05-02T15:18:35.581+0000[0m] {[34mconfigprovider.py:[0m998} INFO[0m - Found endpoint for s3 via: environment_service.[0m
[2025-05-02T15:18:35.611+0000] {process_utils.py:190} INFO - [[34m2025-05-02T15:18:35.611+0000[0m] {[34mscript.py:[0m131} INFO[0m - Processed dataset saved successfully to s3://data/processed/stroke_data.csv[0m
[2025-05-02T15:18:35.612+0000] {process_utils.py:190} INFO - [[34m2025-05-02T15:18:35.611+0000[0m] {[34mscript.py:[0m137} INFO[0m - Updating dataset information in S3/Minio[0m
[2025-05-02T15:18:35.619+0000] {process_utils.py:190} INFO - [[34m2025-05-02T15:18:35.618+0000[0m] {[34mcredentials.py:[0m1213} INFO[0m - Found credentials in environment variables.[0m
[2025-05-02T15:18:35.682+0000] {process_utils.py:190} INFO - [[34m2025-05-02T15:18:35.682+0000[0m] {[34mconfigprovider.py:[0m998} INFO[0m - Found endpoint for s3 via: environment_service.[0m
[2025-05-02T15:18:35.695+0000] {process_utils.py:190} INFO - [[34m2025-05-02T15:18:35.695+0000[0m] {[34mscript.py:[0m152} INFO[0m - No existing dataset information found, initializing new info dictionary[0m
[2025-05-02T15:18:35.701+0000] {process_utils.py:190} INFO - [[34m2025-05-02T15:18:35.700+0000[0m] {[34mscript.py:[0m167} INFO[0m - Target column for dataset: log_cnt[0m
[2025-05-02T15:18:35.704+0000] {process_utils.py:190} INFO - Traceback (most recent call last):
[2025-05-02T15:18:35.704+0000] {process_utils.py:190} INFO -   File "/tmp/venv-call_q98sfru/script.py", line 229, in <module>
[2025-05-02T15:18:35.705+0000] {process_utils.py:190} INFO -     res = feature_engineering(*arg_dict["args"], **arg_dict["kwargs"])
[2025-05-02T15:18:35.705+0000] {process_utils.py:190} INFO -   File "/tmp/venv-call_q98sfru/script.py", line 170, in feature_engineering
[2025-05-02T15:18:35.706+0000] {process_utils.py:190} INFO -     dataset_log = df.drop(columns=target_col)
[2025-05-02T15:18:35.706+0000] {process_utils.py:190} INFO -   File "/home/***/.local/lib/python3.8/site-packages/pandas/core/frame.py", line 5258, in drop
[2025-05-02T15:18:35.706+0000] {process_utils.py:190} INFO -     return super().drop(
[2025-05-02T15:18:35.707+0000] {process_utils.py:190} INFO -   File "/home/***/.local/lib/python3.8/site-packages/pandas/core/generic.py", line 4549, in drop
[2025-05-02T15:18:35.708+0000] {process_utils.py:190} INFO -     obj = obj._drop_axis(labels, axis, level=level, errors=errors)
[2025-05-02T15:18:35.708+0000] {process_utils.py:190} INFO -   File "/home/***/.local/lib/python3.8/site-packages/pandas/core/generic.py", line 4591, in _drop_axis
[2025-05-02T15:18:35.708+0000] {process_utils.py:190} INFO -     new_axis = axis.drop(labels, errors=errors)
[2025-05-02T15:18:35.709+0000] {process_utils.py:190} INFO -   File "/home/***/.local/lib/python3.8/site-packages/pandas/core/indexes/base.py", line 6699, in drop
[2025-05-02T15:18:35.709+0000] {process_utils.py:190} INFO -     raise KeyError(f"{list(labels[mask])} not found in axis")
[2025-05-02T15:18:35.710+0000] {process_utils.py:190} INFO - KeyError: "['log_cnt'] not found in axis"
[2025-05-02T15:18:36.032+0000] {taskinstance.py:2698} ERROR - Task failed with exception
Traceback (most recent call last):
  File "/home/airflow/.local/lib/python3.8/site-packages/airflow/models/taskinstance.py", line 433, in _execute_task
    result = execute_callable(context=context, **execute_callable_kwargs)
  File "/home/airflow/.local/lib/python3.8/site-packages/airflow/decorators/base.py", line 241, in execute
    return_value = super().execute(context)
  File "/home/airflow/.local/lib/python3.8/site-packages/airflow/operators/python.py", line 400, in execute
    return super().execute(context=serializable_context)
  File "/home/airflow/.local/lib/python3.8/site-packages/airflow/operators/python.py", line 199, in execute
    return_value = self.execute_callable()
  File "/home/airflow/.local/lib/python3.8/site-packages/airflow/operators/python.py", line 716, in execute_callable
    result = self._execute_python_callable_in_subprocess(python_path)
  File "/home/airflow/.local/lib/python3.8/site-packages/airflow/operators/python.py", line 471, in _execute_python_callable_in_subprocess
    raise AirflowException(error_msg) from None
airflow.exceptions.AirflowException: Process returned non-zero exit status 1.
"['log_cnt'] not found in axis"
[2025-05-02T15:18:36.035+0000] {taskinstance.py:1138} INFO - Marking task as FAILED. dag_id=process_etl_stroke_data, task_id=feature_engineering, execution_date=20250501T000000, start_date=20250502T151829, end_date=20250502T151836
[2025-05-02T15:18:36.046+0000] {standard_task_runner.py:107} ERROR - Failed to execute job 4 for task feature_engineering (Process returned non-zero exit status 1.
"['log_cnt'] not found in axis"; 886)
[2025-05-02T15:18:36.081+0000] {local_task_job_runner.py:234} INFO - Task exited with return code 1
[2025-05-02T15:18:36.100+0000] {taskinstance.py:3280} INFO - 0 downstream tasks scheduled from follow-on schedule check
