[2025-05-03T00:23:47.967+0000] {taskinstance.py:1956} INFO - Dependencies all met for dep_context=non-requeueable deps ti=<TaskInstance: process_etl_stroke_data_v3.get_original_data scheduled__2025-05-02T00:00:00+00:00 [queued]>
[2025-05-03T00:23:47.974+0000] {taskinstance.py:1956} INFO - Dependencies all met for dep_context=requeueable deps ti=<TaskInstance: process_etl_stroke_data_v3.get_original_data scheduled__2025-05-02T00:00:00+00:00 [queued]>
[2025-05-03T00:23:47.975+0000] {taskinstance.py:2170} INFO - Starting attempt 2 of 2
[2025-05-03T00:23:47.988+0000] {taskinstance.py:2191} INFO - Executing <Task(_PythonVirtualenvDecoratedOperator): get_original_data> on 2025-05-02 00:00:00+00:00
[2025-05-03T00:23:47.992+0000] {standard_task_runner.py:60} INFO - Started process 1192 to run task
[2025-05-03T00:23:47.995+0000] {standard_task_runner.py:87} INFO - Running: ['***', 'tasks', 'run', 'process_etl_stroke_data_v3', 'get_original_data', 'scheduled__2025-05-02T00:00:00+00:00', '--job-id', '3', '--raw', '--subdir', 'DAGS_FOLDER/etl_processing.py', '--cfg-path', '/tmp/tmpo6adl72g']
[2025-05-03T00:23:47.998+0000] {standard_task_runner.py:88} INFO - Job 3: Subtask get_original_data
[2025-05-03T00:23:48.038+0000] {task_command.py:423} INFO - Running <TaskInstance: process_etl_stroke_data_v3.get_original_data scheduled__2025-05-02T00:00:00+00:00 [running]> on host b5903f3da971
[2025-05-03T00:23:48.089+0000] {taskinstance.py:2480} INFO - Exporting env vars: AIRFLOW_CTX_DAG_OWNER='Brain Stroke Project' AIRFLOW_CTX_DAG_ID='process_etl_stroke_data_v3' AIRFLOW_CTX_TASK_ID='get_original_data' AIRFLOW_CTX_EXECUTION_DATE='2025-05-02T00:00:00+00:00' AIRFLOW_CTX_TRY_NUMBER='2' AIRFLOW_CTX_DAG_RUN_ID='scheduled__2025-05-02T00:00:00+00:00'
[2025-05-03T00:23:48.091+0000] {process_utils.py:182} INFO - Executing cmd: /usr/local/bin/python -m virtualenv /tmp/venv9flmclva --system-site-packages --python=python
[2025-05-03T00:23:48.096+0000] {process_utils.py:186} INFO - Output:
[2025-05-03T00:23:48.694+0000] {process_utils.py:190} INFO - created virtual environment CPython3.8.18.final.0-64 in 339ms
[2025-05-03T00:23:48.695+0000] {process_utils.py:190} INFO -   creator CPython3Posix(dest=/tmp/venv9flmclva, clear=False, no_vcs_ignore=False, global=True)
[2025-05-03T00:23:48.695+0000] {process_utils.py:190} INFO -   seeder FromAppData(download=False, pip=bundle, setuptools=bundle, wheel=bundle, via=copy, app_data_dir=/tmp/tmpicscpzvx)
[2025-05-03T00:23:48.696+0000] {process_utils.py:190} INFO -     added seed packages: pip==23.3.1, setuptools==69.0.2, wheel==0.42.0
[2025-05-03T00:23:48.696+0000] {process_utils.py:190} INFO -   activators BashActivator,CShellActivator,FishActivator,NushellActivator,PowerShellActivator,PythonActivator
[2025-05-03T00:23:48.721+0000] {process_utils.py:182} INFO - Executing cmd: /tmp/venv9flmclva/bin/pip install -r /tmp/venv9flmclva/requirements.txt
[2025-05-03T00:23:48.726+0000] {process_utils.py:186} INFO - Output:
[2025-05-03T00:23:49.303+0000] {process_utils.py:190} INFO - WARNING: The directory '/home/***/.cache/pip' or its parent directory is not owned or is not writable by the current user. The cache has been disabled. Check the permissions and owner of that directory. If executing pip with sudo, you should use sudo's -H flag.
[2025-05-03T00:23:49.511+0000] {process_utils.py:190} INFO - Collecting awswrangler==3.9.1 (from -r /tmp/venv9flmclva/requirements.txt (line 1))
[2025-05-03T00:23:49.777+0000] {process_utils.py:190} INFO -   Downloading awswrangler-3.9.1-py3-none-any.whl.metadata (17 kB)
[2025-05-03T00:23:49.780+0000] {process_utils.py:190} INFO - Requirement already satisfied: mlflow>=2.8.0 in /home/***/.local/lib/python3.8/site-packages (from -r /tmp/venv9flmclva/requirements.txt (line 2)) (2.17.2)
[2025-05-03T00:23:49.781+0000] {process_utils.py:190} INFO - Requirement already satisfied: pandas in /home/***/.local/lib/python3.8/site-packages (from -r /tmp/venv9flmclva/requirements.txt (line 3)) (2.0.3)
[2025-05-03T00:23:49.811+0000] {process_utils.py:190} INFO - Requirement already satisfied: boto3<2.0.0,>=1.20.32 in /home/***/.local/lib/python3.8/site-packages (from awswrangler==3.9.1->-r /tmp/venv9flmclva/requirements.txt (line 1)) (1.37.38)
[2025-05-03T00:23:49.812+0000] {process_utils.py:190} INFO - Requirement already satisfied: botocore<2.0.0,>=1.23.32 in /home/***/.local/lib/python3.8/site-packages (from awswrangler==3.9.1->-r /tmp/venv9flmclva/requirements.txt (line 1)) (1.37.38)
[2025-05-03T00:23:49.812+0000] {process_utils.py:190} INFO - Requirement already satisfied: numpy<2.0,>=1.18 in /home/***/.local/lib/python3.8/site-packages (from awswrangler==3.9.1->-r /tmp/venv9flmclva/requirements.txt (line 1)) (1.24.4)
[2025-05-03T00:23:49.813+0000] {process_utils.py:190} INFO - Requirement already satisfied: packaging<25.0,>=21.1 in /home/***/.local/lib/python3.8/site-packages (from awswrangler==3.9.1->-r /tmp/venv9flmclva/requirements.txt (line 1)) (23.2)
[2025-05-03T00:23:49.813+0000] {process_utils.py:190} INFO - Requirement already satisfied: pyarrow>=8.0.0 in /home/***/.local/lib/python3.8/site-packages (from awswrangler==3.9.1->-r /tmp/venv9flmclva/requirements.txt (line 1)) (14.0.2)
[2025-05-03T00:23:49.814+0000] {process_utils.py:190} INFO - Requirement already satisfied: typing-extensions<5.0.0,>=4.4.0 in /home/***/.local/lib/python3.8/site-packages (from awswrangler==3.9.1->-r /tmp/venv9flmclva/requirements.txt (line 1)) (4.9.0)
[2025-05-03T00:23:49.847+0000] {process_utils.py:190} INFO - Requirement already satisfied: mlflow-skinny==2.17.2 in /home/***/.local/lib/python3.8/site-packages (from mlflow>=2.8.0->-r /tmp/venv9flmclva/requirements.txt (line 2)) (2.17.2)
[2025-05-03T00:23:49.848+0000] {process_utils.py:190} INFO - Requirement already satisfied: Flask<4 in /home/***/.local/lib/python3.8/site-packages (from mlflow>=2.8.0->-r /tmp/venv9flmclva/requirements.txt (line 2)) (2.2.5)
[2025-05-03T00:23:49.848+0000] {process_utils.py:190} INFO - Requirement already satisfied: alembic!=1.10.0,<2 in /home/***/.local/lib/python3.8/site-packages (from mlflow>=2.8.0->-r /tmp/venv9flmclva/requirements.txt (line 2)) (1.13.1)
[2025-05-03T00:23:49.849+0000] {process_utils.py:190} INFO - Requirement already satisfied: docker<8,>=4.0.0 in /home/***/.local/lib/python3.8/site-packages (from mlflow>=2.8.0->-r /tmp/venv9flmclva/requirements.txt (line 2)) (7.0.0)
[2025-05-03T00:23:49.850+0000] {process_utils.py:190} INFO - Requirement already satisfied: graphene<4 in /home/***/.local/lib/python3.8/site-packages (from mlflow>=2.8.0->-r /tmp/venv9flmclva/requirements.txt (line 2)) (3.4.3)
[2025-05-03T00:23:49.855+0000] {process_utils.py:190} INFO - Requirement already satisfied: markdown<4,>=3.3 in /home/***/.local/lib/python3.8/site-packages (from mlflow>=2.8.0->-r /tmp/venv9flmclva/requirements.txt (line 2)) (3.5.2)
[2025-05-03T00:23:49.856+0000] {process_utils.py:190} INFO - Requirement already satisfied: matplotlib<4 in /home/***/.local/lib/python3.8/site-packages (from mlflow>=2.8.0->-r /tmp/venv9flmclva/requirements.txt (line 2)) (3.7.5)
[2025-05-03T00:23:49.857+0000] {process_utils.py:190} INFO - Requirement already satisfied: scikit-learn<2 in /home/***/.local/lib/python3.8/site-packages (from mlflow>=2.8.0->-r /tmp/venv9flmclva/requirements.txt (line 2)) (1.3.2)
[2025-05-03T00:23:49.857+0000] {process_utils.py:190} INFO - Requirement already satisfied: scipy<2 in /home/***/.local/lib/python3.8/site-packages (from mlflow>=2.8.0->-r /tmp/venv9flmclva/requirements.txt (line 2)) (1.10.1)
[2025-05-03T00:23:49.858+0000] {process_utils.py:190} INFO - Requirement already satisfied: sqlalchemy<3,>=1.4.0 in /home/***/.local/lib/python3.8/site-packages (from mlflow>=2.8.0->-r /tmp/venv9flmclva/requirements.txt (line 2)) (1.4.51)
[2025-05-03T00:23:49.858+0000] {process_utils.py:190} INFO - Requirement already satisfied: Jinja2<4,>=2.11 in /home/***/.local/lib/python3.8/site-packages (from mlflow>=2.8.0->-r /tmp/venv9flmclva/requirements.txt (line 2)) (3.1.3)
[2025-05-03T00:23:49.862+0000] {process_utils.py:190} INFO - Requirement already satisfied: gunicorn<24 in /home/***/.local/lib/python3.8/site-packages (from mlflow>=2.8.0->-r /tmp/venv9flmclva/requirements.txt (line 2)) (21.2.0)
[2025-05-03T00:23:49.886+0000] {process_utils.py:190} INFO - Requirement already satisfied: cachetools<6,>=5.0.0 in /home/***/.local/lib/python3.8/site-packages (from mlflow-skinny==2.17.2->mlflow>=2.8.0->-r /tmp/venv9flmclva/requirements.txt (line 2)) (5.3.2)
[2025-05-03T00:23:49.887+0000] {process_utils.py:190} INFO - Requirement already satisfied: click<9,>=7.0 in /home/***/.local/lib/python3.8/site-packages (from mlflow-skinny==2.17.2->mlflow>=2.8.0->-r /tmp/venv9flmclva/requirements.txt (line 2)) (8.1.7)
[2025-05-03T00:23:49.887+0000] {process_utils.py:190} INFO - Requirement already satisfied: cloudpickle<4 in /home/***/.local/lib/python3.8/site-packages (from mlflow-skinny==2.17.2->mlflow>=2.8.0->-r /tmp/venv9flmclva/requirements.txt (line 2)) (3.1.1)
[2025-05-03T00:23:49.888+0000] {process_utils.py:190} INFO - Requirement already satisfied: databricks-sdk<1,>=0.20.0 in /home/***/.local/lib/python3.8/site-packages (from mlflow-skinny==2.17.2->mlflow>=2.8.0->-r /tmp/venv9flmclva/requirements.txt (line 2)) (0.51.0)
[2025-05-03T00:23:49.889+0000] {process_utils.py:190} INFO - Requirement already satisfied: gitpython<4,>=3.1.9 in /home/***/.local/lib/python3.8/site-packages (from mlflow-skinny==2.17.2->mlflow>=2.8.0->-r /tmp/venv9flmclva/requirements.txt (line 2)) (3.1.44)
[2025-05-03T00:23:49.889+0000] {process_utils.py:190} INFO - Requirement already satisfied: importlib-metadata!=4.7.0,<9,>=3.7.0 in /home/***/.local/lib/python3.8/site-packages (from mlflow-skinny==2.17.2->mlflow>=2.8.0->-r /tmp/venv9flmclva/requirements.txt (line 2)) (6.11.0)
[2025-05-03T00:23:49.890+0000] {process_utils.py:190} INFO - Requirement already satisfied: opentelemetry-api<3,>=1.9.0 in /home/***/.local/lib/python3.8/site-packages (from mlflow-skinny==2.17.2->mlflow>=2.8.0->-r /tmp/venv9flmclva/requirements.txt (line 2)) (1.22.0)
[2025-05-03T00:23:49.891+0000] {process_utils.py:190} INFO - Requirement already satisfied: opentelemetry-sdk<3,>=1.9.0 in /home/***/.local/lib/python3.8/site-packages (from mlflow-skinny==2.17.2->mlflow>=2.8.0->-r /tmp/venv9flmclva/requirements.txt (line 2)) (1.22.0)
[2025-05-03T00:23:49.891+0000] {process_utils.py:190} INFO - Requirement already satisfied: protobuf<6,>=3.12.0 in /home/***/.local/lib/python3.8/site-packages (from mlflow-skinny==2.17.2->mlflow>=2.8.0->-r /tmp/venv9flmclva/requirements.txt (line 2)) (4.25.2)
[2025-05-03T00:23:49.892+0000] {process_utils.py:190} INFO - Requirement already satisfied: pyyaml<7,>=5.1 in /home/***/.local/lib/python3.8/site-packages (from mlflow-skinny==2.17.2->mlflow>=2.8.0->-r /tmp/venv9flmclva/requirements.txt (line 2)) (6.0.1)
[2025-05-03T00:23:49.892+0000] {process_utils.py:190} INFO - Requirement already satisfied: requests<3,>=2.17.3 in /home/***/.local/lib/python3.8/site-packages (from mlflow-skinny==2.17.2->mlflow>=2.8.0->-r /tmp/venv9flmclva/requirements.txt (line 2)) (2.31.0)
[2025-05-03T00:23:49.893+0000] {process_utils.py:190} INFO - Requirement already satisfied: sqlparse<1,>=0.4.0 in /home/***/.local/lib/python3.8/site-packages (from mlflow-skinny==2.17.2->mlflow>=2.8.0->-r /tmp/venv9flmclva/requirements.txt (line 2)) (0.4.4)
[2025-05-03T00:23:49.951+0000] {process_utils.py:190} INFO - Requirement already satisfied: python-dateutil>=2.8.2 in /home/***/.local/lib/python3.8/site-packages (from pandas->-r /tmp/venv9flmclva/requirements.txt (line 3)) (2.8.2)
[2025-05-03T00:23:49.952+0000] {process_utils.py:190} INFO - Requirement already satisfied: pytz>=2020.1 in /home/***/.local/lib/python3.8/site-packages (from pandas->-r /tmp/venv9flmclva/requirements.txt (line 3)) (2023.3.post1)
[2025-05-03T00:23:49.952+0000] {process_utils.py:190} INFO - Requirement already satisfied: tzdata>=2022.1 in /home/***/.local/lib/python3.8/site-packages (from pandas->-r /tmp/venv9flmclva/requirements.txt (line 3)) (2023.4)
[2025-05-03T00:23:49.969+0000] {process_utils.py:190} INFO - Requirement already satisfied: Mako in /home/***/.local/lib/python3.8/site-packages (from alembic!=1.10.0,<2->mlflow>=2.8.0->-r /tmp/venv9flmclva/requirements.txt (line 2)) (1.3.0)
[2025-05-03T00:23:49.969+0000] {process_utils.py:190} INFO - Requirement already satisfied: importlib-resources in /home/***/.local/lib/python3.8/site-packages (from alembic!=1.10.0,<2->mlflow>=2.8.0->-r /tmp/venv9flmclva/requirements.txt (line 2)) (5.13.0)
[2025-05-03T00:23:49.973+0000] {process_utils.py:190} INFO - Requirement already satisfied: jmespath<2.0.0,>=0.7.1 in /home/***/.local/lib/python3.8/site-packages (from boto3<2.0.0,>=1.20.32->awswrangler==3.9.1->-r /tmp/venv9flmclva/requirements.txt (line 1)) (0.10.0)
[2025-05-03T00:23:49.974+0000] {process_utils.py:190} INFO - Requirement already satisfied: s3transfer<0.12.0,>=0.11.0 in /home/***/.local/lib/python3.8/site-packages (from boto3<2.0.0,>=1.20.32->awswrangler==3.9.1->-r /tmp/venv9flmclva/requirements.txt (line 1)) (0.11.5)
[2025-05-03T00:23:49.979+0000] {process_utils.py:190} INFO - Requirement already satisfied: urllib3<1.27,>=1.25.4 in /home/***/.local/lib/python3.8/site-packages (from botocore<2.0.0,>=1.23.32->awswrangler==3.9.1->-r /tmp/venv9flmclva/requirements.txt (line 1)) (1.26.18)
[2025-05-03T00:23:49.990+0000] {process_utils.py:190} INFO - Requirement already satisfied: Werkzeug>=2.2.2 in /home/***/.local/lib/python3.8/site-packages (from Flask<4->mlflow>=2.8.0->-r /tmp/venv9flmclva/requirements.txt (line 2)) (2.2.3)
[2025-05-03T00:23:49.991+0000] {process_utils.py:190} INFO - Requirement already satisfied: itsdangerous>=2.0 in /home/***/.local/lib/python3.8/site-packages (from Flask<4->mlflow>=2.8.0->-r /tmp/venv9flmclva/requirements.txt (line 2)) (2.1.2)
[2025-05-03T00:23:50.006+0000] {process_utils.py:190} INFO - Requirement already satisfied: graphql-core<3.3,>=3.1 in /home/***/.local/lib/python3.8/site-packages (from graphene<4->mlflow>=2.8.0->-r /tmp/venv9flmclva/requirements.txt (line 2)) (3.2.6)
[2025-05-03T00:23:50.007+0000] {process_utils.py:190} INFO - Requirement already satisfied: graphql-relay<3.3,>=3.1 in /home/***/.local/lib/python3.8/site-packages (from graphene<4->mlflow>=2.8.0->-r /tmp/venv9flmclva/requirements.txt (line 2)) (3.2.0)
[2025-05-03T00:23:50.015+0000] {process_utils.py:190} INFO - Requirement already satisfied: MarkupSafe>=2.0 in /home/***/.local/lib/python3.8/site-packages (from Jinja2<4,>=2.11->mlflow>=2.8.0->-r /tmp/venv9flmclva/requirements.txt (line 2)) (2.1.3)
[2025-05-03T00:23:50.033+0000] {process_utils.py:190} INFO - Requirement already satisfied: contourpy>=1.0.1 in /home/***/.local/lib/python3.8/site-packages (from matplotlib<4->mlflow>=2.8.0->-r /tmp/venv9flmclva/requirements.txt (line 2)) (1.1.1)
[2025-05-03T00:23:50.041+0000] {process_utils.py:190} INFO - Requirement already satisfied: cycler>=0.10 in /home/***/.local/lib/python3.8/site-packages (from matplotlib<4->mlflow>=2.8.0->-r /tmp/venv9flmclva/requirements.txt (line 2)) (0.12.1)
[2025-05-03T00:23:50.046+0000] {process_utils.py:190} INFO - Requirement already satisfied: fonttools>=4.22.0 in /home/***/.local/lib/python3.8/site-packages (from matplotlib<4->mlflow>=2.8.0->-r /tmp/venv9flmclva/requirements.txt (line 2)) (4.57.0)
[2025-05-03T00:23:50.047+0000] {process_utils.py:190} INFO - Requirement already satisfied: kiwisolver>=1.0.1 in /home/***/.local/lib/python3.8/site-packages (from matplotlib<4->mlflow>=2.8.0->-r /tmp/venv9flmclva/requirements.txt (line 2)) (1.4.7)
[2025-05-03T00:23:50.047+0000] {process_utils.py:190} INFO - Requirement already satisfied: pillow>=6.2.0 in /home/***/.local/lib/python3.8/site-packages (from matplotlib<4->mlflow>=2.8.0->-r /tmp/venv9flmclva/requirements.txt (line 2)) (10.4.0)
[2025-05-03T00:23:50.048+0000] {process_utils.py:190} INFO - Requirement already satisfied: pyparsing>=2.3.1 in /home/***/.local/lib/python3.8/site-packages (from matplotlib<4->mlflow>=2.8.0->-r /tmp/venv9flmclva/requirements.txt (line 2)) (3.1.1)
[2025-05-03T00:23:50.049+0000] {process_utils.py:190} INFO - Requirement already satisfied: six>=1.5 in /home/***/.local/lib/python3.8/site-packages (from python-dateutil>=2.8.2->pandas->-r /tmp/venv9flmclva/requirements.txt (line 3)) (1.16.0)
[2025-05-03T00:23:50.067+0000] {process_utils.py:190} INFO - Requirement already satisfied: joblib>=1.1.1 in /home/***/.local/lib/python3.8/site-packages (from scikit-learn<2->mlflow>=2.8.0->-r /tmp/venv9flmclva/requirements.txt (line 2)) (1.4.2)
[2025-05-03T00:23:50.068+0000] {process_utils.py:190} INFO - Requirement already satisfied: threadpoolctl>=2.0.0 in /home/***/.local/lib/python3.8/site-packages (from scikit-learn<2->mlflow>=2.8.0->-r /tmp/venv9flmclva/requirements.txt (line 2)) (3.5.0)
[2025-05-03T00:23:50.131+0000] {process_utils.py:190} INFO - Requirement already satisfied: greenlet!=0.4.17 in /home/***/.local/lib/python3.8/site-packages (from sqlalchemy<3,>=1.4.0->mlflow>=2.8.0->-r /tmp/venv9flmclva/requirements.txt (line 2)) (3.0.3)
[2025-05-03T00:23:50.181+0000] {process_utils.py:190} INFO - Requirement already satisfied: google-auth~=2.0 in /home/***/.local/lib/python3.8/site-packages (from databricks-sdk<1,>=0.20.0->mlflow-skinny==2.17.2->mlflow>=2.8.0->-r /tmp/venv9flmclva/requirements.txt (line 2)) (2.26.2)
[2025-05-03T00:23:50.223+0000] {process_utils.py:190} INFO - Requirement already satisfied: gitdb<5,>=4.0.1 in /home/***/.local/lib/python3.8/site-packages (from gitpython<4,>=3.1.9->mlflow-skinny==2.17.2->mlflow>=2.8.0->-r /tmp/venv9flmclva/requirements.txt (line 2)) (4.0.12)
[2025-05-03T00:23:50.255+0000] {process_utils.py:190} INFO - Requirement already satisfied: zipp>=0.5 in /home/***/.local/lib/python3.8/site-packages (from importlib-metadata!=4.7.0,<9,>=3.7.0->mlflow-skinny==2.17.2->mlflow>=2.8.0->-r /tmp/venv9flmclva/requirements.txt (line 2)) (3.17.0)
[2025-05-03T00:23:50.290+0000] {process_utils.py:190} INFO - Requirement already satisfied: deprecated>=1.2.6 in /home/***/.local/lib/python3.8/site-packages (from opentelemetry-api<3,>=1.9.0->mlflow-skinny==2.17.2->mlflow>=2.8.0->-r /tmp/venv9flmclva/requirements.txt (line 2)) (1.2.14)
[2025-05-03T00:23:50.295+0000] {process_utils.py:190} INFO - Requirement already satisfied: opentelemetry-semantic-conventions==0.43b0 in /home/***/.local/lib/python3.8/site-packages (from opentelemetry-sdk<3,>=1.9.0->mlflow-skinny==2.17.2->mlflow>=2.8.0->-r /tmp/venv9flmclva/requirements.txt (line 2)) (0.43b0)
[2025-05-03T00:23:50.335+0000] {process_utils.py:190} INFO - Requirement already satisfied: charset-normalizer<4,>=2 in /home/***/.local/lib/python3.8/site-packages (from requests<3,>=2.17.3->mlflow-skinny==2.17.2->mlflow>=2.8.0->-r /tmp/venv9flmclva/requirements.txt (line 2)) (3.3.2)
[2025-05-03T00:23:50.336+0000] {process_utils.py:190} INFO - Requirement already satisfied: idna<4,>=2.5 in /home/***/.local/lib/python3.8/site-packages (from requests<3,>=2.17.3->mlflow-skinny==2.17.2->mlflow>=2.8.0->-r /tmp/venv9flmclva/requirements.txt (line 2)) (3.6)
[2025-05-03T00:23:50.336+0000] {process_utils.py:190} INFO - Requirement already satisfied: certifi>=2017.4.17 in /home/***/.local/lib/python3.8/site-packages (from requests<3,>=2.17.3->mlflow-skinny==2.17.2->mlflow>=2.8.0->-r /tmp/venv9flmclva/requirements.txt (line 2)) (2023.11.17)
[2025-05-03T00:23:50.406+0000] {process_utils.py:190} INFO - Requirement already satisfied: wrapt<2,>=1.10 in /home/***/.local/lib/python3.8/site-packages (from deprecated>=1.2.6->opentelemetry-api<3,>=1.9.0->mlflow-skinny==2.17.2->mlflow>=2.8.0->-r /tmp/venv9flmclva/requirements.txt (line 2)) (1.16.0)
[2025-05-03T00:23:50.411+0000] {process_utils.py:190} INFO - Requirement already satisfied: smmap<6,>=3.0.1 in /home/***/.local/lib/python3.8/site-packages (from gitdb<5,>=4.0.1->gitpython<4,>=3.1.9->mlflow-skinny==2.17.2->mlflow>=2.8.0->-r /tmp/venv9flmclva/requirements.txt (line 2)) (5.0.2)
[2025-05-03T00:23:50.424+0000] {process_utils.py:190} INFO - Requirement already satisfied: pyasn1-modules>=0.2.1 in /home/***/.local/lib/python3.8/site-packages (from google-auth~=2.0->databricks-sdk<1,>=0.20.0->mlflow-skinny==2.17.2->mlflow>=2.8.0->-r /tmp/venv9flmclva/requirements.txt (line 2)) (0.3.0)
[2025-05-03T00:23:50.424+0000] {process_utils.py:190} INFO - Requirement already satisfied: rsa<5,>=3.1.4 in /home/***/.local/lib/python3.8/site-packages (from google-auth~=2.0->databricks-sdk<1,>=0.20.0->mlflow-skinny==2.17.2->mlflow>=2.8.0->-r /tmp/venv9flmclva/requirements.txt (line 2)) (4.9)
[2025-05-03T00:23:50.453+0000] {process_utils.py:190} INFO - Requirement already satisfied: pyasn1<0.6.0,>=0.4.6 in /home/***/.local/lib/python3.8/site-packages (from pyasn1-modules>=0.2.1->google-auth~=2.0->databricks-sdk<1,>=0.20.0->mlflow-skinny==2.17.2->mlflow>=2.8.0->-r /tmp/venv9flmclva/requirements.txt (line 2)) (0.5.1)
[2025-05-03T00:23:50.496+0000] {process_utils.py:190} INFO - Downloading awswrangler-3.9.1-py3-none-any.whl (381 kB)
[2025-05-03T00:23:50.518+0000] {process_utils.py:190} INFO -    ━━━━━━━━━━━━━━━━━━━━━━━━━━━━━━━━━━━━━━━━ 381.7/381.7 kB 20.1 MB/s eta 0:00:00
[2025-05-03T00:23:52.225+0000] {process_utils.py:190} INFO - Installing collected packages: awswrangler
[2025-05-03T00:23:52.399+0000] {process_utils.py:190} INFO - Successfully installed awswrangler-3.9.1
[2025-05-03T00:23:52.483+0000] {process_utils.py:190} INFO - 
[2025-05-03T00:23:52.484+0000] {process_utils.py:190} INFO - [notice] A new release of pip is available: 23.3.1 -> 25.0.1
[2025-05-03T00:23:52.484+0000] {process_utils.py:190} INFO - [notice] To update, run: python -m pip install --upgrade pip
[2025-05-03T00:23:52.625+0000] {process_utils.py:182} INFO - Executing cmd: /tmp/venv9flmclva/bin/python /tmp/venv-callz46za2ux/script.py /tmp/venv-callz46za2ux/script.in /tmp/venv-callz46za2ux/script.out /tmp/venv-callz46za2ux/string_args.txt /tmp/venv-callz46za2ux/termination.log
[2025-05-03T00:23:52.631+0000] {process_utils.py:186} INFO - Output:
[2025-05-03T00:23:53.308+0000] {process_utils.py:190} INFO - WARNING:root:/opt/***/logs/scheduler/latest already exists as a dir/file. Skip creating symlink.
[2025-05-03T00:23:54.583+0000] {process_utils.py:190} INFO - [[34m2025-05-03T00:23:54.582+0000[0m] {[34mscript.py:[0m49} INFO[0m - Starting to read the dataset from /opt/***/dataset/healthcare-dataset-stroke-data.csv[0m
[2025-05-03T00:23:54.604+0000] {process_utils.py:190} INFO - [[34m2025-05-03T00:23:54.604+0000[0m] {[34mscript.py:[0m59} INFO[0m - Dataset read successfully from /opt/***/dataset/healthcare-dataset-stroke-data.csv[0m
[2025-05-03T00:23:54.605+0000] {process_utils.py:190} INFO - [[34m2025-05-03T00:23:54.604+0000[0m] {[34mscript.py:[0m60} INFO[0m - Dataset shape: (5110, 12)[0m
[2025-05-03T00:23:54.606+0000] {process_utils.py:190} INFO - [[34m2025-05-03T00:23:54.605+0000[0m] {[34mscript.py:[0m76} INFO[0m - Dataset columns: ['id', 'gender', 'age', 'hypertension', 'heart_disease', 'ever_married', 'work_type', 'residence_type', 'avg_glucose_level', 'bmi', 'smoking_status', 'stroke'][0m
[2025-05-03T00:23:54.635+0000] {process_utils.py:190} INFO - [[34m2025-05-03T00:23:54.634+0000[0m] {[34mconnectionpool.py:[0m824} WARNING[0m - Retrying (JitteredRetry(total=4, connect=4, read=5, redirect=5, status=5)) after connection broken by 'NewConnectionError('<urllib3.connection.HTTPConnection object at 0x7f050826d9d0>: Failed to establish a new connection: [Errno 111] Connection refused')': /api/2.0/mlflow/experiments/get-by-name?experiment_name=Stroke+Prediction[0m
[2025-05-03T00:23:58.641+0000] {process_utils.py:190} INFO - [[34m2025-05-03T00:23:58.640+0000[0m] {[34mconnectionpool.py:[0m824} WARNING[0m - Retrying (JitteredRetry(total=3, connect=3, read=5, redirect=5, status=5)) after connection broken by 'NewConnectionError('<urllib3.connection.HTTPConnection object at 0x7f050826d970>: Failed to establish a new connection: [Errno 111] Connection refused')': /api/2.0/mlflow/experiments/get-by-name?experiment_name=Stroke+Prediction[0m
[2025-05-03T00:24:06.651+0000] {process_utils.py:190} INFO - [[34m2025-05-03T00:24:06.650+0000[0m] {[34mconnectionpool.py:[0m824} WARNING[0m - Retrying (JitteredRetry(total=2, connect=2, read=5, redirect=5, status=5)) after connection broken by 'NewConnectionError('<urllib3.connection.HTTPConnection object at 0x7f05661f0d60>: Failed to establish a new connection: [Errno 111] Connection refused')': /api/2.0/mlflow/experiments/get-by-name?experiment_name=Stroke+Prediction[0m
[2025-05-03T00:24:22.669+0000] {process_utils.py:190} INFO - [[34m2025-05-03T00:24:22.669+0000[0m] {[34mconnectionpool.py:[0m824} WARNING[0m - Retrying (JitteredRetry(total=1, connect=1, read=5, redirect=5, status=5)) after connection broken by 'NewConnectionError('<urllib3.connection.HTTPConnection object at 0x7f05077838b0>: Failed to establish a new connection: [Errno 111] Connection refused')': /api/2.0/mlflow/experiments/get-by-name?experiment_name=Stroke+Prediction[0m
[2025-05-03T00:24:54.678+0000] {process_utils.py:190} INFO - [[34m2025-05-03T00:24:54.677+0000[0m] {[34mconnectionpool.py:[0m824} WARNING[0m - Retrying (JitteredRetry(total=0, connect=0, read=5, redirect=5, status=5)) after connection broken by 'NewConnectionError('<urllib3.connection.HTTPConnection object at 0x7f0507783a60>: Failed to establish a new connection: [Errno 111] Connection refused')': /api/2.0/mlflow/experiments/get-by-name?experiment_name=Stroke+Prediction[0m
[2025-05-03T00:24:54.680+0000] {process_utils.py:190} INFO - [[34m2025-05-03T00:24:54.680+0000[0m] {[34mscript.py:[0m109} ERROR[0m - Error al leer el archivo CSV: API request to http://mlflow:5000/api/2.0/mlflow/experiments/get-by-name failed with exception HTTPConnectionPool(host='mlflow', port=5000): Max retries exceeded with url: /api/2.0/mlflow/experiments/get-by-name?experiment_name=Stroke+Prediction (Caused by NewConnectionError('<urllib3.connection.HTTPConnection object at 0x7f0507783790>: Failed to establish a new connection: [Errno 111] Connection refused'))[0m
[2025-05-03T00:24:54.683+0000] {process_utils.py:190} INFO - Traceback (most recent call last):
[2025-05-03T00:24:54.685+0000] {process_utils.py:190} INFO -   File "/home/***/.local/lib/python3.8/site-packages/urllib3/connection.py", line 174, in _new_conn
[2025-05-03T00:24:54.687+0000] {process_utils.py:190} INFO -     conn = connection.create_connection(
[2025-05-03T00:24:54.688+0000] {process_utils.py:190} INFO -   File "/home/***/.local/lib/python3.8/site-packages/urllib3/util/connection.py", line 95, in create_connection
[2025-05-03T00:24:54.689+0000] {process_utils.py:190} INFO -     raise err
[2025-05-03T00:24:54.691+0000] {process_utils.py:190} INFO -   File "/home/***/.local/lib/python3.8/site-packages/urllib3/util/connection.py", line 85, in create_connection
[2025-05-03T00:24:54.693+0000] {process_utils.py:190} INFO -     sock.connect(sa)
[2025-05-03T00:24:54.695+0000] {process_utils.py:190} INFO - ConnectionRefusedError: [Errno 111] Connection refused
[2025-05-03T00:24:54.699+0000] {process_utils.py:190} INFO - 
[2025-05-03T00:24:54.701+0000] {process_utils.py:190} INFO - During handling of the above exception, another exception occurred:
[2025-05-03T00:24:54.703+0000] {process_utils.py:190} INFO - 
[2025-05-03T00:24:54.705+0000] {process_utils.py:190} INFO - Traceback (most recent call last):
[2025-05-03T00:24:54.705+0000] {process_utils.py:190} INFO -   File "/home/***/.local/lib/python3.8/site-packages/urllib3/connectionpool.py", line 715, in urlopen
[2025-05-03T00:24:54.707+0000] {process_utils.py:190} INFO -     httplib_response = self._make_request(
[2025-05-03T00:24:54.708+0000] {process_utils.py:190} INFO -   File "/home/***/.local/lib/python3.8/site-packages/urllib3/connectionpool.py", line 416, in _make_request
[2025-05-03T00:24:54.710+0000] {process_utils.py:190} INFO -     conn.request(method, url, **httplib_request_kw)
[2025-05-03T00:24:54.712+0000] {process_utils.py:190} INFO -   File "/home/***/.local/lib/python3.8/site-packages/urllib3/connection.py", line 244, in request
[2025-05-03T00:24:54.714+0000] {process_utils.py:190} INFO -     super(HTTPConnection, self).request(method, url, body=body, headers=headers)
[2025-05-03T00:24:54.716+0000] {process_utils.py:190} INFO -   File "/usr/local/lib/python3.8/http/client.py", line 1256, in request
[2025-05-03T00:24:54.720+0000] {process_utils.py:190} INFO -     self._send_request(method, url, body, headers, encode_chunked)
[2025-05-03T00:24:54.722+0000] {process_utils.py:190} INFO -   File "/usr/local/lib/python3.8/http/client.py", line 1302, in _send_request
[2025-05-03T00:24:54.724+0000] {process_utils.py:190} INFO -     self.endheaders(body, encode_chunked=encode_chunked)
[2025-05-03T00:24:54.726+0000] {process_utils.py:190} INFO -   File "/usr/local/lib/python3.8/http/client.py", line 1251, in endheaders
[2025-05-03T00:24:54.728+0000] {process_utils.py:190} INFO -     self._send_output(message_body, encode_chunked=encode_chunked)
[2025-05-03T00:24:54.730+0000] {process_utils.py:190} INFO -   File "/usr/local/lib/python3.8/http/client.py", line 1011, in _send_output
[2025-05-03T00:24:54.732+0000] {process_utils.py:190} INFO -     self.send(msg)
[2025-05-03T00:24:54.734+0000] {process_utils.py:190} INFO -   File "/usr/local/lib/python3.8/http/client.py", line 951, in send
[2025-05-03T00:24:54.736+0000] {process_utils.py:190} INFO -     self.connect()
[2025-05-03T00:24:54.740+0000] {process_utils.py:190} INFO -   File "/home/***/.local/lib/python3.8/site-packages/urllib3/connection.py", line 205, in connect
[2025-05-03T00:24:54.741+0000] {process_utils.py:190} INFO -     conn = self._new_conn()
[2025-05-03T00:24:54.742+0000] {process_utils.py:190} INFO -   File "/home/***/.local/lib/python3.8/site-packages/urllib3/connection.py", line 186, in _new_conn
[2025-05-03T00:24:54.744+0000] {process_utils.py:190} INFO -     raise NewConnectionError(
[2025-05-03T00:24:54.746+0000] {process_utils.py:190} INFO - urllib3.exceptions.NewConnectionError: <urllib3.connection.HTTPConnection object at 0x7f0507783790>: Failed to establish a new connection: [Errno 111] Connection refused
[2025-05-03T00:24:54.748+0000] {process_utils.py:190} INFO - 
[2025-05-03T00:24:54.752+0000] {process_utils.py:190} INFO - During handling of the above exception, another exception occurred:
[2025-05-03T00:24:54.756+0000] {process_utils.py:190} INFO - 
[2025-05-03T00:24:54.758+0000] {process_utils.py:190} INFO - Traceback (most recent call last):
[2025-05-03T00:24:54.760+0000] {process_utils.py:190} INFO -   File "/home/***/.local/lib/python3.8/site-packages/requests/adapters.py", line 486, in send
[2025-05-03T00:24:54.762+0000] {process_utils.py:190} INFO -     resp = conn.urlopen(
[2025-05-03T00:24:54.764+0000] {process_utils.py:190} INFO -   File "/home/***/.local/lib/python3.8/site-packages/urllib3/connectionpool.py", line 827, in urlopen
[2025-05-03T00:24:54.765+0000] {process_utils.py:190} INFO -     return self.urlopen(
[2025-05-03T00:24:54.766+0000] {process_utils.py:190} INFO -   File "/home/***/.local/lib/python3.8/site-packages/urllib3/connectionpool.py", line 827, in urlopen
[2025-05-03T00:24:54.770+0000] {process_utils.py:190} INFO -     return self.urlopen(
[2025-05-03T00:24:54.772+0000] {process_utils.py:190} INFO -   File "/home/***/.local/lib/python3.8/site-packages/urllib3/connectionpool.py", line 827, in urlopen
[2025-05-03T00:24:54.774+0000] {process_utils.py:190} INFO -     return self.urlopen(
[2025-05-03T00:24:54.775+0000] {process_utils.py:190} INFO -   [Previous line repeated 2 more times]
[2025-05-03T00:24:54.777+0000] {process_utils.py:190} INFO -   File "/home/***/.local/lib/python3.8/site-packages/urllib3/connectionpool.py", line 799, in urlopen
[2025-05-03T00:24:54.779+0000] {process_utils.py:190} INFO -     retries = retries.increment(
[2025-05-03T00:24:54.781+0000] {process_utils.py:190} INFO -   File "/home/***/.local/lib/python3.8/site-packages/urllib3/util/retry.py", line 592, in increment
[2025-05-03T00:24:54.782+0000] {process_utils.py:190} INFO -     raise MaxRetryError(_pool, url, error or ResponseError(cause))
[2025-05-03T00:24:54.785+0000] {process_utils.py:190} INFO - urllib3.exceptions.MaxRetryError: HTTPConnectionPool(host='mlflow', port=5000): Max retries exceeded with url: /api/2.0/mlflow/experiments/get-by-name?experiment_name=Stroke+Prediction (Caused by NewConnectionError('<urllib3.connection.HTTPConnection object at 0x7f0507783790>: Failed to establish a new connection: [Errno 111] Connection refused'))
[2025-05-03T00:24:54.787+0000] {process_utils.py:190} INFO - 
[2025-05-03T00:24:54.789+0000] {process_utils.py:190} INFO - During handling of the above exception, another exception occurred:
[2025-05-03T00:24:54.793+0000] {process_utils.py:190} INFO - 
[2025-05-03T00:24:54.795+0000] {process_utils.py:190} INFO - Traceback (most recent call last):
[2025-05-03T00:24:54.797+0000] {process_utils.py:190} INFO -   File "/home/***/.local/lib/python3.8/site-packages/mlflow/utils/rest_utils.py", line 189, in http_request
[2025-05-03T00:24:54.801+0000] {process_utils.py:190} INFO -     return _get_http_response_with_retries(
[2025-05-03T00:24:54.803+0000] {process_utils.py:190} INFO -   File "/home/***/.local/lib/python3.8/site-packages/mlflow/utils/request_utils.py", line 237, in _get_http_response_with_retries
[2025-05-03T00:24:54.804+0000] {process_utils.py:190} INFO -     return session.request(method, url, allow_redirects=allow_redirects, **kwargs)
[2025-05-03T00:24:54.806+0000] {process_utils.py:190} INFO -   File "/home/***/.local/lib/python3.8/site-packages/requests/sessions.py", line 589, in request
[2025-05-03T00:24:54.810+0000] {process_utils.py:190} INFO -     resp = self.send(prep, **send_kwargs)
[2025-05-03T00:24:54.812+0000] {process_utils.py:190} INFO -   File "/home/***/.local/lib/python3.8/site-packages/requests/sessions.py", line 703, in send
[2025-05-03T00:24:54.814+0000] {process_utils.py:190} INFO -     r = adapter.send(request, **kwargs)
[2025-05-03T00:24:54.816+0000] {process_utils.py:190} INFO -   File "/home/***/.local/lib/python3.8/site-packages/requests/adapters.py", line 519, in send
[2025-05-03T00:24:54.818+0000] {process_utils.py:190} INFO -     raise ConnectionError(e, request=request)
[2025-05-03T00:24:54.819+0000] {process_utils.py:190} INFO - requests.exceptions.ConnectionError: HTTPConnectionPool(host='mlflow', port=5000): Max retries exceeded with url: /api/2.0/mlflow/experiments/get-by-name?experiment_name=Stroke+Prediction (Caused by NewConnectionError('<urllib3.connection.HTTPConnection object at 0x7f0507783790>: Failed to establish a new connection: [Errno 111] Connection refused'))
[2025-05-03T00:24:54.821+0000] {process_utils.py:190} INFO - 
[2025-05-03T00:24:54.823+0000] {process_utils.py:190} INFO - During handling of the above exception, another exception occurred:
[2025-05-03T00:24:54.827+0000] {process_utils.py:190} INFO - 
[2025-05-03T00:24:54.851+0000] {process_utils.py:190} INFO - Traceback (most recent call last):
[2025-05-03T00:24:54.852+0000] {process_utils.py:190} INFO -   File "/tmp/venv-callz46za2ux/script.py", line 123, in <module>
[2025-05-03T00:24:54.853+0000] {process_utils.py:190} INFO -     res = get_data(*arg_dict["args"], **arg_dict["kwargs"])
[2025-05-03T00:24:54.853+0000] {process_utils.py:190} INFO -   File "/tmp/venv-callz46za2ux/script.py", line 80, in get_data
[2025-05-03T00:24:54.854+0000] {process_utils.py:190} INFO -     experiment = mlflow.set_experiment("Stroke Prediction")
[2025-05-03T00:24:54.854+0000] {process_utils.py:190} INFO -   File "/home/***/.local/lib/python3.8/site-packages/mlflow/tracking/fluent.py", line 145, in set_experiment
[2025-05-03T00:24:54.855+0000] {process_utils.py:190} INFO -     experiment = client.get_experiment_by_name(experiment_name)
[2025-05-03T00:24:54.855+0000] {process_utils.py:190} INFO -   File "/home/***/.local/lib/python3.8/site-packages/mlflow/tracking/client.py", line 1256, in get_experiment_by_name
[2025-05-03T00:24:54.856+0000] {process_utils.py:190} INFO -     return self._tracking_client.get_experiment_by_name(name)
[2025-05-03T00:24:54.856+0000] {process_utils.py:190} INFO -   File "/home/***/.local/lib/python3.8/site-packages/mlflow/tracking/_tracking_service/client.py", line 501, in get_experiment_by_name
[2025-05-03T00:24:54.857+0000] {process_utils.py:190} INFO -     return self.store.get_experiment_by_name(name)
[2025-05-03T00:24:54.857+0000] {process_utils.py:190} INFO -   File "/home/***/.local/lib/python3.8/site-packages/mlflow/store/tracking/rest_store.py", line 519, in get_experiment_by_name
[2025-05-03T00:24:54.857+0000] {process_utils.py:190} INFO -     response_proto = self._call_endpoint(GetExperimentByName, req_body)
[2025-05-03T00:24:54.857+0000] {process_utils.py:190} INFO -   File "/home/***/.local/lib/python3.8/site-packages/mlflow/store/tracking/rest_store.py", line 82, in _call_endpoint
[2025-05-03T00:24:54.858+0000] {process_utils.py:190} INFO -     return call_endpoint(self.get_host_creds(), endpoint, method, json_body, response_proto)
[2025-05-03T00:24:54.858+0000] {process_utils.py:190} INFO -   File "/home/***/.local/lib/python3.8/site-packages/mlflow/utils/rest_utils.py", line 365, in call_endpoint
[2025-05-03T00:24:54.858+0000] {process_utils.py:190} INFO -     response = http_request(**call_kwargs)
[2025-05-03T00:24:54.859+0000] {process_utils.py:190} INFO -   File "/home/***/.local/lib/python3.8/site-packages/mlflow/utils/rest_utils.py", line 212, in http_request
[2025-05-03T00:24:54.859+0000] {process_utils.py:190} INFO -     raise MlflowException(f"API request to {url} failed with exception {e}")
[2025-05-03T00:24:54.860+0000] {process_utils.py:190} INFO - mlflow.exceptions.MlflowException: API request to http://mlflow:5000/api/2.0/mlflow/experiments/get-by-name failed with exception HTTPConnectionPool(host='mlflow', port=5000): Max retries exceeded with url: /api/2.0/mlflow/experiments/get-by-name?experiment_name=Stroke+Prediction (Caused by NewConnectionError('<urllib3.connection.HTTPConnection object at 0x7f0507783790>: Failed to establish a new connection: [Errno 111] Connection refused'))
[2025-05-03T00:24:54.956+0000] {taskinstance.py:2698} ERROR - Task failed with exception
Traceback (most recent call last):
  File "/home/airflow/.local/lib/python3.8/site-packages/airflow/models/taskinstance.py", line 433, in _execute_task
    result = execute_callable(context=context, **execute_callable_kwargs)
  File "/home/airflow/.local/lib/python3.8/site-packages/airflow/decorators/base.py", line 241, in execute
    return_value = super().execute(context)
  File "/home/airflow/.local/lib/python3.8/site-packages/airflow/operators/python.py", line 400, in execute
    return super().execute(context=serializable_context)
  File "/home/airflow/.local/lib/python3.8/site-packages/airflow/operators/python.py", line 199, in execute
    return_value = self.execute_callable()
  File "/home/airflow/.local/lib/python3.8/site-packages/airflow/operators/python.py", line 716, in execute_callable
    result = self._execute_python_callable_in_subprocess(python_path)
  File "/home/airflow/.local/lib/python3.8/site-packages/airflow/operators/python.py", line 471, in _execute_python_callable_in_subprocess
    raise AirflowException(error_msg) from None
airflow.exceptions.AirflowException: Process returned non-zero exit status 1.
API request to http://mlflow:5000/api/2.0/mlflow/experiments/get-by-name failed with exception HTTPConnectionPool(host='mlflow', port=5000): Max retries exceeded with url: /api/2.0/mlflow/experiments/get-by-name?experiment_name=Stroke+Prediction (Caused by NewConnectionError('<urllib3.connection.HTTPConnection object at 0x7f0507783790>: Failed to establish a new connection: [Errno 111] Connection refused'))
[2025-05-03T00:24:54.961+0000] {taskinstance.py:1138} INFO - Marking task as FAILED. dag_id=process_etl_stroke_data_v3, task_id=get_original_data, execution_date=20250502T000000, start_date=20250503T002347, end_date=20250503T002454
[2025-05-03T00:24:54.974+0000] {standard_task_runner.py:107} ERROR - Failed to execute job 3 for task get_original_data (Process returned non-zero exit status 1.
API request to http://mlflow:5000/api/2.0/mlflow/experiments/get-by-name failed with exception HTTPConnectionPool(host='mlflow', port=5000): Max retries exceeded with url: /api/2.0/mlflow/experiments/get-by-name?experiment_name=Stroke+Prediction (Caused by NewConnectionError('<urllib3.connection.HTTPConnection object at 0x7f0507783790>: Failed to establish a new connection: [Errno 111] Connection refused')); 1192)
[2025-05-03T00:24:54.999+0000] {local_task_job_runner.py:234} INFO - Task exited with return code 1
[2025-05-03T00:24:55.019+0000] {taskinstance.py:3280} INFO - 0 downstream tasks scheduled from follow-on schedule check
